fg2: <main> function()
  block 0: [entry]
    node 0: constant[undefined,v1] (test-resources/src/flowgraphbuilder/switchWithCall.js)
    node 1: function-decl[function f(),-]* (test-resources/src/flowgraphbuilder/switchWithCall.js:1:1)
    ->[block 1]
  block 1:
    node 2: constant["tajs-host-env:string-replace-model.js",v2] (host-environment-sources-loader)
    node 3: constant[true,v3] (host-environment-sources-loader)
    ->[block 2]
  block 2:
    node 4: call[TAJS_load,v2,v3,v4] (host-environment-sources-loader)
    ->[block 3]
  block 3:
    node 5: call[-,v4,-] (host-environment-sources-loader)
    ->[block 4]
  block 4:
    node 6: constant[42.0,v5] (test-resources/src/flowgraphbuilder/switchWithCall.js:2:9)
    node 7: read-variable['f',v9,v8] (test-resources/src/flowgraphbuilder/switchWithCall.js:3:10)
    ->[block 5]
  block 5:
    node 8: call[v8,v9,v6] (test-resources/src/flowgraphbuilder/switchWithCall.js:3:10)
    ->[block 6]
  block 6:
    node 9: ===[v5,v6,v7] (test-resources/src/flowgraphbuilder/switchWithCall.js:2:1)
    node 10: if[v7](true-block:7,false-block:7) (test-resources/src/flowgraphbuilder/switchWithCall.js:2:1)
    ->[block 7]
  block 7: [exit-ordinary]
    node 11: return[v1] (test-resources/src/flowgraphbuilder/switchWithCall.js)
    ->[]
  block 8: [exit-exceptional]
    node 12: exceptional-return (test-resources/src/flowgraphbuilder/switchWithCall.js)
    ->[]
function f()
  block 9: [entry]
    node 13: constant[undefined,v1] (test-resources/src/flowgraphbuilder/switchWithCall.js:1:1)
    ->[block 10]
  block 10: [exit-ordinary]
    node 14: return[v1] (test-resources/src/flowgraphbuilder/switchWithCall.js:1:1)
    ->[]
  block 11: [exit-exceptional]
    node 15: exceptional-return (test-resources/src/flowgraphbuilder/switchWithCall.js:1:1)
    ->[]

test-resources/src/flowgraphbuilder/switchWithCall.js:2:1: [definite] The conditional expression is always false
test-resources/src/flowgraphbuilder/switchWithCall.js: [definite] Exceptional program exit is unreachable
Soundness testing succeeded for 7 checks (with 0 expected failures)
